Workbook

Sheet Executive Dashboard
A1: HSBC | AI DELIVERY CONTROL TOWER
A4: PROJECT START | B4: 46251 | D4: HARD DEADLINE | E4: NOV 2026 | G4: CORE TEAM | H4: 3 | J4: PLANNED PEAK TEAM | K4: 5
A6: Overall Health AMBER | E6: Critical Path TBD | I6: Open External Dependencies 10 | M6: SME Risk HIGH
A10: DELIVERY PRINCIPLE
A11: You are accountable for end-to-end delivery: schedule, quality, technical outcome, stakeholder alignment and recovery. The team cannot use 'code not working' as a delivery escape. Technical issues are delivery issues requiring ownership, recovery and escalation.
A14: TOP DELIVERY CONTROLS
A15: 1. Every milestone has one accountable owner and explicit exit criteria.
A16: 2. External dependencies are registered from Day 1 with owner, required-by date, trigger and fallback/recovery action.
A17: 3. SME availability is a planned dependency; validation cannot be scheduled on an assumed 'TBD' slot.
A18: 4. Platform/API/server failures are tracked as delivery dependencies/issues with contingency paths and recovery SLA.
A19: 5. October capacity reduction for Durga Puja and November Diwali capacity reduction are explicitly planned into the schedule.
A20: 6. Monitoring team owns operational monitoring; IT owns monitoring dashboard build. Delivery team supports both.
A21: 7. IT owns deployment/go-live. Delivery team provides support/back-up only; deployment is not a Delivery Lead-owned implementation activity.
A23: KEY MILESTONES
A24: Gate | B24: Milestone | C24: Target Window | D24: Accountable Owner | E24: Dependency | F24: Critical? | G24: Exit Criteria | H24: Status
A25: M1 | B25: Scope & Delivery Baseline | C25: 17–21 Aug | D25: Delivery Lead | E25: Business scope / R&C validation | F25: Yes | G25: Scope, assumptions, plan and governance route agreed | H25: Not Started
A26: M2 | B26: Data Readiness | C26: 24 Aug–4 Sep | D26: Senior Data Scientist | E26: REGMAP/Helios access; data availability | F26: Yes | G26: Coverage, field and quality assessment complete; gaps owned | H26: Not Started
A27: M3 | B27: Linkage Solution Build | C27: 31 Aug–25 Sep | D27: Russel – Senior AI Developer | E27: M2; historical linked dataset | F27: Yes | G27: Candidate methods/prompt/retrieval approaches ready | H27: Not Started
A28: M4 | B28: Linkage Evaluation & Selection | C28: 21 Sep–2 Oct | D28: Delivery Lead + Russel | E28: Golden/evaluation dataset; agreed methodology | F28: Yes | G28: Baseline, evaluation, benchmark and method decision complete | H28: Not Started
A29: M5 | B29: Linkage SME Validation | C29: 5–9 Oct | D29: Delivery Lead | E29: SME availability | F29: Yes | G29: SME validation complete or formal exception/escalation recorded | H29: Not Started
A30: M6 | B30: Impact Assessment Build | C30: 31 Aug–25 Sep | D30: Additional AI Developer* | E30: M2; SME input | F30: Yes | G30: Candidate solution ready for validation | H30: Not Started
A31: M7 | B31: Impact Assessment SME Validation | C31: 5–9 Oct | D31: Delivery Lead | E31: SME availability | F31: Yes | G31: SME validation complete or formal exception/escalation recorded | H31: Not Started
A32: M8 | B32: Production Readiness | C32: 12–23 Oct | D32: Russel + AI Developers | E32: M5/M7; code/documentation/KT | F32: Yes | G32: Code modularised, documented, tested and KT-ready | H32: Not Started
A33: M9 | B33: Monitoring Readiness | C33: 12–30 Oct | D33: Monitoring Team + IT | E33: Monitoring team capacity; IT dashboard | F33: Yes | G33: Monitoring process ready; IT dashboard available/accepted | H33: Not Started
A34: M10 | B34: Governance Approval Gate | C34: 12–30 Oct | D34: Delivery Lead + Sponsor | E34: Governance reviewers / documentation | F34: Yes | G34: Required governance documents/approvals complete | H34: Not Started
A35: M11 | B35: Deployment Readiness | C35: 2–13 Nov | D35: IT (Delivery support) | E35: M8/M9/M10 | F35: Yes | G35: IT confirms deployment readiness | H35: Not Started
A36: M12 | B36: Go-Live | C36: Nov 2026 | D36: IT GHeadache; Delivery Support | E36: M11 | F36: Yes | G36: IT deploys; Delivery validates/supports post-go-live | H36: Not Started
A37: DEADLINE CONTROL
A38: Hard deadline is Nov-2026. Exact day is currently an UNCONFIRMED constraint. Until the contractual/management date is confirmed, the plan uses 13-Nov for operational go-live planning and 20-Nov for post-go-live validation, with recovery capacity reserved.
A41: DELIVERY PLAN VIEW
A42: Use 'Delivery Plan' as the SINGLE SOURCE OF TRUTH. Milestones and activities are on the same sheet. Use the +/- outline controls to collapse all activities for the milestone view or expand only the milestone(s) you are actively managing. Use 'How to Operate' for the operating procedure.
A45: SCHEDULE CONTROL
A46: Delivery Plan now contains Planned, Actual and Forecast dates plus formula-driven working days and predecessor logic. Management Gantt shows milestone-level Planned vs Forecast vs Actual.
A48: M1 / SCOPING STATUS
A49: Scoping is already in progress from 05-Aug-2026 (Delivery Lead + Russel). Management Gantt therefore starts on 05-Aug; the formal remaining project delivery baseline remains controlled through the Delivery Plan.

Sheet How to Operate
A1: HSBC | HOW TO OPERATE THIS DELIVERY CONTROL PLAN
A4: 1. PURPOSE OF THIS WORKBOOK
A5: • This workbook is the project control system, not just a task tracker. It is designed to help the Delivery Lead control scope, schedule, quality, resources, dependencies, governance, risks and delivery outcome.
A6: • The 'Delivery Plan' tab is the SINGLE SOURCE OF TRUTH for milestone and activity-level delivery planning. Do not maintain a second copy of the delivery schedule elsewhere.
A7: • The other tabs are control registers that support the Delivery Plan: Executive Dashboard, Resource & Capacity, External Dependency Register, RAID Log, Governance Tracker, Monitoring & Handover, Assumptions & Calendar, RACI, Critical Path and Management Resource Ask.
A8: 2. THE DELIVERY PLAN — HOW TO READ IT
A9: • The Delivery Plan has two levels in ONE sheet: MILESTONE rows (M1–M12) and ACTIVITY rows (e.g., M1.1, M1.2, M1.3).
A10: • By default, activities are collapsed. This gives you the 12-milestone management view.
A11: • Use Excel's outline +/- controls on the LEFT side of the sheet to expand or contract the activity rows under each milestone.
A12: • Expand only the milestone you are actively managing. Example: expand M5 during SME validation week; contract M5 again for the management view.
A13: • Do NOT create separate milestone and activity copies. The hierarchy is intentionally designed so one sheet serves both management and execution.
A14: 3. DAILY OPERATING MODEL FOR THE DELIVERY LEAD
A15: Start of day | C15: Open Delivery Plan and look at milestone status, Critical Path? and External Dependency? fields.
A16: Then | C16: Expand the milestones that are active in the current 1–2 week window and review their activities.
A17: Control | C17: Check every activity that is due soon: owner, dependency, status, exit criteria and recovery action.
A18: External check | C18: Open External Dependency Register and verify every dependency due within the next 2 weeks has an owner and a credible fallback.
A19: RAID check | C19: Review RAID Log for new risks/issues and confirm every High/Critical item has an owner and action.
A20: Capacity check | C20: Review Resource & Capacity, especially around October Durga Puja and November Diwali availability.
A21: End of day | C21: Update status and comments only where something materially changed; do not turn the plan into a diary.
A22: 4. WEEKLY DELIVERY CONTROL — YOUR CORE REVIEW
A23: • 1) Milestones: What moved this week vs plan? What did not?
A24: • 2) Critical path: Has any critical milestone moved to Amber/Red or lost recovery buffer?
A25: • 3) Dependencies: Which external dependency can derail the next 1–2 weeks?
A26: • 4) Resources: Is the team size/capacity still sufficient? Are SME, Monitoring Team or IT resources actually committed?
A27: • 5) Quality: Are deliverables meeting their exit criteria, or are we declaring activities 'done' without evidence?
A28: • 6) Governance: Are documents and approvals progressing in parallel, or becoming end-loaded?
A29: • 7) Recovery: For every Amber/Red item, what is the recovery action, owner and date?
A30: 5. HOW TO UPDATE STATUS
A31: • Not Started = work has not begun.
A32: • Green = progressing to plan and exit criteria remain achievable within the planned date.
A33: • Amber = a threat exists to scope/date/quality, but recovery is credible and actively owned.
... A112: • The Management Gantt begins on 05-Aug-2026 because M1 scoping is already in progress. The remaining delivery baseline can still be controlled from the formal project start of 17-Aug-2026.

Sheet Delivery Plan
A1: HSBC | DELIVERY PLAN — LIVE SCHEDULE CONTROL
A3: ID | B3: Workstream | C3: Milestone / Activity | D3: Accountable Owner | E3: Predecessor(s) | F3: Planned Start | G3: Planned End | H3: Planned Working Days | I3: Actual Start | J3: Actual End | K3: Actual Working Days | L3: Forecast Start | M3: Forecast End | N3: Forecast Working Days | O3: Exit / Acceptance Criteria | P3: Status | Q3: Critical Path? | R3: External Dependency? | S3: Contingency / Recovery Action | T3: Leave / Capacity Impact | U3: Risk / Issue | V3: Comments
A4: M1 | B4: Scope | C4: Scope & Delivery Baseline | D4: Delivery Lead | F4: =IF(COUNT(F5:F7)=0,"",MIN(F5:F7)) -> 46239 | G4: =IF(COUNT(G5:G7)=0,"",MAX(G5:G7)) | H4: =IF(OR(F4="",G4=""),"",NETWORKDAYS.INTL(F4,G4,1,'Schedule Calendar'!$H$6:$H$30)) | I4: =IF(COUNT(I5:I7)=0,"",MIN(I5:I7)) | K4: =IF(OR(I4="",J4=""),"",NETWORKDAYS.INTL(I4,J4,1,'Schedule Calendar'!$H$6:$H$30)) | L4: =IFERROR(MIN(L5:L7),"") -> 46239 | M4: =IFERROR(MAX(M5:M7),"") -> 46289 | N4: =IF(OR(L4="",M4=""),"",NETWORKDAYS.INTL(L4,M4,1,'Schedule Calendar'!$H$6:$H$30)) -> 37 | O4: Milestone exit criteria defined in the operating model | P4: Green | Q4: =IF(COUNTIF(Q5:Q7,"Yes")>0,"Yes","No") -> Yes | R4: =IF(COUNTIF(R5:R7,"Yes")>0,"Yes","No") -> Yes | S4: See External Dependency Register / RAID Log | T4: October Durga Puja + November Diwali capacity impact | U4: Scoping document currently in progress; Delivery Lead + Russel are drafting. | V4: Gantt starts 05-Aug-2026 to reflect work already underway.
A5: M1.1 | B5: Scope | C5: Scope document sign-off | D5: Delivery Lead | F5: 46239 | G5: 19-Aug-26 | H5: =IF(OR(F5="",G5=""),"",NETWORKDAYS.INTL(F5,G5,1,'Schedule Calendar'!$H$6:$H$30)) -> 11 | K5: =IF(OR(I5="",J5=""),"",NETWORKDAYS.INTL(I5,J5,1,'Schedule Calendar'!$H$6:$H$30)) | L5: =IF(I5<>"",I5,F5) -> 46239 | M5: =IF(J5<>"",J5,IF(OR(L5="",H5=""),"",WORKDAY(L5,H5-1,'Schedule Calendar'!$H$6:$H$30))) -> 46253 | N5: =IF(OR(L5="",M5=""),"",NETWORKDAYS.INTL(L5,M5,1,'Schedule Calendar'!$H$6:$H$30)) -> 11 | O5: Scope and objectives approved | P5: Not Started | Q5: Yes | R5: Yes | S5: Escalate same day if required stakeholder unavailable; document decision/assumption and protect baseline. | T5: None
A6: M1.2 | B6: Scope | C6: R&C Impact Assessment outcome validation | D6: Delivery Lead | E6: M1.1 | F6: 46239 | G6: 21-Aug-26 | H6: =IF(OR(F6="",G6=""),"",NETWORKDAYS.INTL(F6,G6,1,'Schedule Calendar'!$H$6:$H$30)) -> 13 | K6: =IF(OR(I6="",J6=""),"",NETWORKDAYS.INTL(I6,J6,1,'Schedule Calendar'!$H$6:$H$30)) | L6: =IF(I6<>"",I6,MAX(F6,WORKDAY(MAX(M5),1,'Schedule Calendar'!$H$6:$H$30))) -> 46254 | M6: =IF(J6<>"",J6,IF(OR(L6="",H6=""),"",WORKDAY(L6,H6-1,'Schedule Calendar'!$H$6:$H$30))) -> 46272 | N6: =IF(OR(L6="",M6=""),"",NETWORKDAYS.INTL(L6,M6,1,'Schedule Calendar'!$H$6:$H$30)) -> 13 | O6: Outcome validated and open questions assigned | P6: Not Started | Q6: Yes | R6: Yes | S6: Pre-book stakeholder session; nominate delegate if primary unavailable. | T6: None
A7: M1.3 | B7: Scope | C7: Delivery baseline, RAID and dependency register | D7: Delivery Lead | E7: M1.1, M1.2 | F7: 46239 | G7: 21-Aug-26 | H7: =IF(OR(F7="",G7=""),"",NETWORKDAYS.INTL(F7,G7,1,'Schedule Calendar'!$H$6:$H$30)) -> 13 | K7: =IF(OR(I7="",J7=""),"",NETWORKDAYS.INTL(I7,J7,1,'Schedule Calendar'!$H$6:$H$30)) | L7: =IF(I7<>"",I7,MAX(F7,WORKDAY(MAX(M5,M6),1,'Schedule Calendar'!$H$6:$H$30))) -> 46273 | M7: =IF(J7<>"",J7,IF(OR(L7="",H7=""),"",WORKDAY(L7,H7-1,'Schedule Calendar'!$H$6:$H$30))) -> 46289 | N7: =IF(OR(L7="",M7=""),"",NETWORKDAYS.INTL(L7,M7,1,'Schedule Calendar'!$H$6:$H$30)) -> 13 | O7: Integrated plan, RAID and dependency controls live | P7: Not Started | Q7: Yes | R7: No | S7: N/A | T7: None
A8: M2 | B8: EDA | C8: Data Readiness | D8: Senior Data Scientist | E8: M1 | F8: =IF(COUNT(F9:F14)=0,"",MIN(F9:F14)) | G8: =IF(COUNT(G9:G14)=0,"",MAX(G9:G14)) | H8: =IF(OR(F8="",G8=""),"",NETWORKDAYS.INTL(F8,G8,1,'Schedule Calendar'!$H$6:$H$30)) | I8: =IF(COUNT(I9:I14)=0,"",MIN(I9:I14)) | K8: =IF(OR(I8="",J8=""),"",NETWORKDAYS.INTL(I8,J8,1,'Schedule Calendar'!$H$6:$H$30)) | L8: =IFERROR(MIN(L9:L14),"") -> 46290 | M8: =IFERROR(MAX(M9:M14),"") -> 46323 | N8: =IF(OR(L8="",M8=""),"",NETWORKDAYS.INTL(L8,M8,1,'Schedule Calendar'!$H$6:$H$30)) -> 24 | O8: Milestone exit criteria defined in the operating model | P8: =IF(COUNTIF(P9:P14,"Red")>0,"Red",IF(COUNTIF(P9:P14,"Amber")>0,"Amber",IF(COUNTIF(P9:P14,"Blocked")>0,"Blocked",IF(COUNTIF(P9:P14,"Complete")=ROWS(P9:P14),"Complete",IF(COUNTIF(P9:P14,"Green")>0,"Green","Not Started"))))) -> Not Started | Q8: =IF(COUNTIF(Q9:Q14,"Yes")>0,"Yes","No") -> Yes | R8: =IF(COUNTIF(R9:R14,"Yes")>0,"Yes","No") -> Yes | S8: See External Dependency Register / RAID Log | T8: October Durga Puja + November Diwali capacity impact
A9: M2.1 | B9: EDA | C9: REGMAP EDA | D9: Senior Data Scientist / Junior Data Scientist | E9: M1 | F9: 24-Aug-26 | G9: 28-Aug-26 | H9: =IF(OR(F9="",G9=""),"",NETWORKDAYS.INTL(F9,G9,1,'Schedule Calendar'!$H$6:$H$30)) -> 5 | K9: =IF(OR(I9="",J9=""),"",NETWORKDAYS.INTL(I9,J9,1,'Schedule Calendar'!$H$6:$H$30)) | L9: =IF(I9<>"",I9,MAX(F9,WORKDAY(MAX(M4),1,'Schedule Calendar'!$H$6:$H$30))) -> 46290 | M9: =IF(J9<>"",J9,IF(OR(L9="",H9=""),"",WORKDAY(L9,H9-1,'Schedule Calendar'!$H$6:$H$30))) -> 46296 | N9: =IF(OR(L9="",M9=""),"",NETWORKDAYS.INTL(L9,M9,1,'Schedule Calendar'!$H$6:$H$30)) -> 5 | O9: EDA complete; usable population quantified | P9: Not Started | Q9: Yes | R9: Yes | S9: Escalate access; use approved alternative extract if available; re-sequence non-dependent work. | T9: None
A10: M2.2 | B10: EDA | C10: Helios EDA | D10: Senior Data Scientist / Junior Data Scientist | E10: M2.1 | F10: 24-Aug-26 | G10: 28-Aug-26 | H10: =IF(OR(F10="",G10=""),"",NETWORKDAYS.INTL(F10,G10,1,'Schedule Calendar'!$H$6:$H$30)) -> 5 | K10: =IF(OR(I10="",J10=""),"",NETWORKDAYS.INTL(I10,J10,1,'Schedule Calendar'!$H$6:$H$30)) | L10: =IF(I10<>"",I10,MAX(F10,WORKDAY(MAX(M9),1,'Schedule Calendar'!$H$6:$H$30))) -> 46297 | M10: =IF(J10<>"",J10,IF(OR(L10="",H10=""),"",WORKDAY(L10,H10-1,'Schedule Calendar'!$H$6:$H$30))) -> 46303 | N10: =IF(OR(L10="",M10=""),"",NETWORKDAYS.INTL(L10,M10,1,'Schedule Calendar'!$H$6:$H$30)) -> 5 | O10: EDA complete; usable population quantified | P10: Not Started | Q10: Yes | R10: Yes | S10: Same as M2.1. | T10: None
A11: M2.3 | B11: EDA | C11: Data coverage assessment | D11: Junior Data Scientist | E11: M2.1, M2.2 | F11: 31-Aug-26 | G11: 1-Sep-26 | H11: =IF(OR(F11="",G11=""),"",NETWORKDAYS.INTL(F11,G11,1,'Schedule Calendar'!$H$6:$H$30)) -> 2 | K11: =IF(OR(I11="",J11=""),"",NETWORKDAYS.INTL(I11,J11,1,'Schedule Calendar'!$H$6:$H$30)) | L11: =IF(I11<>"",I11,MAX(F11,WORKDAY(MAX(M9,M10),1,'Schedule Calendar'!$H$6:$H$30))) -> 46304 | M11: =IF(J11<>"",J11,IF(OR(L11="",H11=""),"",WORKDAY(L11,H11-1,'Schedule Calendar'!$H$6:$H$30))) -> 46307 | N11: =IF(OR(L11="",M11=""),"",NETWORKDAYS.INTL(L11,M11,1,'Schedule Calendar'!$H$6:$H$30)) -> 2 | O11: Coverage and missingness quantified | P11: Not Started | Q11: Yes | R11: No | S11: Use available extracts; clearly flag coverage gaps. | T11: None
A12: M2.4 | B12: EDA | C12: Data field validation | D12: Junior Data Scientist | E12: M2.1, M2.2 | F12: 31-Aug-26 | G12: 2-Sep-26 | H12: =IF(OR(F12="",G12=""),"",NETWORKDAYS.INTL(F12,G12,1,'Schedule Calendar'!$H$6:$H$30)) -> 3 | K12: =IF(OR(I12="",J12=""),"",NETWORKDAYS.INTL(I12,J12,1,'Schedule Calendar'!$H$6:$H$30)) | L12: =IF(I12<>"",I12,MAX(F12,WORKDAY(MAX(M9,M10),1,'Schedule Calendar'!$H$6:$H$30))) -> 46304 | M12: =IF(J12<>"",J12,IF(OR(L12="",H12=""),"",WORKDAY(L12,H12-1,'Schedule Calendar'!$H$6:$H$30))) -> 46308 | N12: =IF(OR(L12="",M12=""),"",NETWORKDAYS.INTL(L12,M12,1,'Schedule Calendar'!$H$6:$H$30)) -> 3 | O12: Required fields validated | P12: Not Started | Q12: Yes | R12: No | S12: Prioritise critical fields; raise gap decisions immediately. | T12: None
A13: M2.5 | B13: EDA | C13: Data quality assessment | D13: Senior Data Scientist | E13: M2.1, M2.2 | F13: 1-Sep-26 | G13: 4-Sep-26 | H13: =IF(OR(F13="",G13=""),"",NETWORKDAYS.INTL(F13,G13,1,'Schedule Calendar'!$H$6:$H$30)) -> 4 | K13: =IF(OR(I13="",J13=""),"",NETWORKDAYS.INTL(I13,J13,1,'Schedule Calendar'!$H$6:$H$30)) | L13: =IF(I13<>"",I13,MAX(F13,WORKDAY(MAX(M9,M10),1,'Schedule Calendar'!$H$6:$H$30))) -> 46304 | M13: =IF(J13<>"",J13,IF(OR(L13="",H13=""),"",WORKDAY(L13,H13-1,'Schedule Calendar'!$H$6:$H$30))) -> 46309 | N13: =IF(OR(L13="",M13=""),"",NETWORKDAYS.INTL(L13,M13,1,'Schedule Calendar'!$H$6:$H$30)) -> 4 | O13: Quality issues quantified and owners assigned | P13: Not Started | Q13: Yes | R13: No | S13: Create data-quality exception list; do not silently proceed. | T13: None
A14: M2.6 | B14: EDA | C14: Historical linked-alert / labelled dataset readiness | D14: Delivery Lead + Senior Data Scientist | E14: M2.5 | F14: 24-Aug-26 | G14: 4-Sep-26 | H14: =IF(OR(F14="",G14=""),"",NETWORKDAYS.INTL(F14,G14,1,'Schedule Calendar'!$H$6:$H$30)) -> 10 | K14: =IF(OR(I14="",J14=""),"",NETWORKDAYS.INTL(I14,J14,1,'Schedule Calendar'!$H$6:$H$30)) | L14: =IF(I14<>"",I14,MAX(F14,WORKDAY(MAX(M13),1,'Schedule Calendar'!$H$6:$H$30))) -> 46310 | M14: =IF(J14<>"",J14,IF(OR(L14="",H14=""),"",WORKDAY(L14,H14-1,'Schedule Calendar'!$H$6:$H$30))) -> 46323 | N14: =IF(OR(L14="",M14=""),"",NETWORKDAYS.INTL(L14,M14,1,'Schedule Calendar'!$H$6:$H$30)) -> 10 | O14: Sufficient historical linked examples available or explicit limitation accepted | P14: Not Started | Q14: Yes | R14: Yes | S14: Escalate as Day-1 critical dependency; if unavailable, formally document inability to establish credible baseline/evaluation and re-plan decision. | T14: None
A15: M3 | B15: Linkage | C15: Linkage Solution Build | D15: Russel – Senior AI Developer | E15: M2 | F15: =IF(COUNT(F16:F20)=0,"",MIN(F16:F20)) | G15: =IF(COUNT(G16:G20)=0,"",MAX(G16:G20)) | H15: =IF(OR(F15="",G15=""),"",NETWORKDAYS.INTL(F15,G15,1,'Schedule Calendar'!$H$6:$H$30)) | I15: =IF(COUNT(I16:I20)=0,"",MIN(I16:I20)) | K15: =IF(OR(I15="",J15=""),"",NETWORKDAYS.INTL(I15,J15,1,'Schedule Calendar'!$H$6:$H$30)) | L15: =IFERROR(MIN(L16:L20),"") -> 46324 | M15: =IFERROR(MAX(M16:M20),"") -> 46374 | N15: =IF(OR(L15="",M15=""),"",NETWORKDAYS.INTL(L15,M15,1,'Schedule Calendar'!$H$6:$H$30)) -> 37 | O15: Milestone exit criteria defined in the operating model | P15: =IF(COUNTIF(P16:P20,"Red")>0,"Red",IF(COUNTIF(P16:P20,"Amber")>0,"Amber",IF(COUNTIF(P16:P20,"Blocked")>0,"Blocked",IF(COUNTIF(P16:P20,"Complete")=ROWS(P16:P20),"Complete",IF(COUNTIF(P16:P20,"Green")>0,"Green","Not Started"))))) -> Not Started | Q15: =IF(COUNTIF(Q16:Q20,"Yes")>0,"Yes","No") -> Yes | R15: =IF(COUNTIF(R16:R20,"Yes")>0,"Yes","No") -> Yes | S15: See External Dependency Register / RAID Log | T15: October Durga Puja + November Diwali capacity impact
A16: M3.1 | B16: Linkage | C16: Embedding solution development | D16: Russel – Senior AI Developer | E16: M2 | F16: 31-Aug-26 | G16: 11-Sep-26 | H16: =IF(OR(F16="",G16=""),"",NETWORKDAYS.INTL(F16,G16,1,'Schedule Calendar'!$H$6:$H$30)) -> 10 | K16: =IF(OR(I16="",J16=""),"",NETWORKDAYS.INTL(I16,J16,1,'Schedule Calendar'!$H$6:$H$30)) | L16: =IF(I16<>"",I16,MAX(F16,WORKDAY(MAX(M8),1,'Schedule Calendar'!$H$6:$H$30))) -> 46324 | M16: =IF(J16<>"",J16,IF(OR(L16="",H16=""),"",WORKDAY(L16,H16-1,'Schedule Calendar'!$H$6:$H$30))) -> 46337 | N16: =IF(OR(L16="",M16=""),"",NETWORKDAYS.INTL(L16,M16,1,'Schedule Calendar'!$H$6:$H$30)) -> 10 | O16: Candidate embedding approaches implemented | P16: Not Started | Q16: Yes | R16: No | S16: Use alternative approved approach if platform/API unavailable; maintain experiment log. | T16: None
A17: M3.2 | B17: Linkage | C17: Model training / candidate modelling | D17: Russel + AI Developer* | E17: M2 | F17: 7-Sep-26 | G17: 18-Sep-26 | H17: =IF(OR(F17="",G17=""),"",NETWORKDAYS.INTL(F17,G17,1,'Schedule Calendar'!$H$6:$H$30)) -> 10 | K17: =IF(OR(I17="",J17=""),"",NETWORKDAYS.INTL(I17,J17,1,'Schedule Calendar'!$H$6:$H$30)) | L17: =IF(I17<>"",I17,MAX(F17,WORKDAY(MAX(M8),1,'Schedule Calendar'!$H$6:$H$30))) -> 46324 | M17: =IF(J17<>"",J17,IF(OR(L17="",H17=""),"",WORKDAY(L17,H17-1,'Schedule Calendar'!$H$6:$H$30))) -> 46337 | N17: =IF(OR(L17="",M17=""),"",NETWORKDAYS.INTL(L17,M17,1,'Schedule Calendar'!$H$6:$H$30)) -> 10 | O17: Candidate models trained and reproducible | P17: Not Started | Q17: Yes | R17: Yes | S17: Use approved alternate compute environment; queue jobs; escalate capacity outage. | T17: None
A18: M3.3 | B18: Linkage | C18: GenAI solution development | D18: Russel + AI Developer* | E18: M3.2 | F18: 7-Sep-26 | G18: 18-Sep-26 | H18: =IF(OR(F18="",G18=""),"",NETWORKDAYS.INTL(F18,G18,1,'Schedule Calendar'!$H$6:$H$30)) -> 10 | K18: =IF(OR(I18="",J18=""),"",NETWORKDAYS.INTL(I18,J18,1,'Schedule Calendar'!$H$6:$H$30)) | L18: =IF(I18<>"",I18,MAX(F18,WORKDAY(MAX(M17),1,'Schedule Calendar'!$H$6:$H$30))) -> 46338 | M18: =IF(J18<>"",J18,IF(OR(L18="",H18=""),"",WORKDAY(L18,H18-1,'Schedule Calendar'!$H$6:$H$30))) -> 46351 | N18: =IF(OR(L18="",M18=""),"",NETWORKDAYS.INTL(L18,M18,1,'Schedule Calendar'!$H$6:$H$30)) -> 10 | O18: Candidate GenAI approach operational in test environment | P18: Not Started | Q18: Yes | R18: Yes | S18: Maintain fallback model/API where approved; if service outage > agreed threshold, switch to offline testing/review. | T18: None
A19: M3.4 | B19: Linkage | C19: Prompt engineering | D19: AI Developer* + Russel | E19: M3.3 | F19: 10-Sep-26 | G19: 18-Sep-26 | H19: =IF(OR(F19="",G19=""),"",NETWORKDAYS.INTL(F19,G19,1,'Schedule Calendar'!$H$6:$H$30)) -> 7 | K19: =IF(OR(I19="",J19=""),"",NETWORKDAYS.INTL(I19,J19,1,'Schedule Calendar'!$H$6:$H$30)) | L19: =IF(I19<>"",I19,MAX(F19,WORKDAY(MAX(M18),1,'Schedule Calendar'!$H$6:$H$30))) -> 46352 | M19: =IF(J19<>"",J19,IF(OR(L19="",H19=""),"",WORKDAY(L19,H19-1,'Schedule Calendar'!$H$6:$H$30))) -> 46360 | N19: =IF(OR(L19="",M19=""),"",NETWORKDAYS.INTL(L19,M19,1,'Schedule Calendar'!$H$6:$H$30)) -> 7 | O19: Prompt iterations documented with test results | P19: Not Started | Q19: Yes | R19: No | S19: Continue prompt design using cached/test data if live API unavailable. | T19: None
A20: M3.5 | B20: Linkage | C20: Retrieval tuning | D20: AI Developer* + Russel | E20: M3.4 | F20: 14-Sep-26 | G20: 25-Sep-26 | H20: =IF(OR(F20="",G20=""),"",NETWORKDAYS.INTL(F20,G20,1,'Schedule Calendar'!$H$6:$H$30)) -> 10 | K20: =IF(OR(I20="",J20=""),"",NETWORKDAYS.INTL(I20,J20,1,'Schedule Calendar'!$H$6:$H$30)) | L20: =IF(I20<>"",I20,MAX(F20,WORKDAY(MAX(M19),1,'Schedule Calendar'!$H$6:$H$30))) -> 46363 | M20: =IF(J20<>"",J20,IF(OR(L20="",H20=""),"",WORKDAY(L20,H20-1,'Schedule Calendar'!$H$6:$H$30))) -> 46374 | N20: =IF(OR(L20="",M20=""),"",NETWORKDAYS.INTL(L20,M20,1,'Schedule Calendar'!$H$6:$H$30)) -> 10 | O20: Retrieval configuration tuned and evaluated | P20: Not Started | Q20: Yes | R20: Yes | S20: Use offline/indexed test set; restore/rebuild index if service fails. | T20: None
A21: M4 | B21: Linkage | C21: Evaluation & Method Selection | D21: Delivery Lead | E21: M3 | F21: =IF(COUNT(F22:F24)=0,"",MIN(F22:F24)) | G21: =IF(COUNT(G22:G24)=0,"",MAX(G22:G24)) | H21: =IF(OR(F21="",G21=""),"",NETWORKDAYS.INTL(F21,G21,1,'Schedule Calendar'!$H$6:$H$30)) | I21: =IF(COUNT(I22:I24)=0,"",MIN(I22:I24)) | K21: =IF(OR(I21="",J21=""),"",NETWORKDAYS.INTL(I21,J21,1,'Schedule Calendar'!$H$6:$H$30)) | L21: =IFERROR(MIN(L22:L24),"") -> 46377 | M21: =IFERROR(MAX(M22:M24),"") -> 46393 | N21: =IF(OR(L21="",M21=""),"",NETWORKDAYS.INTL(L21,M21,1,'Schedule Calendar'!$H$6:$H$30)) -> 13 | O21: Milestone exit criteria defined in the operating model | P21: =IF(COUNTIF(P22:P24,"Red")>0,"Red",IF(COUNTIF(P22:P24,"Amber")>0,"Amber",IF(COUNTIF(P22:P24,"Blocked")>0,"Blocked",IF(COUNTIF(P22:P24,"Complete")=ROWS(P22:P24),"Complete",IF(COUNTIF(P22:P24,"Green")>0,"Green","Not Started"))))) -> Not Started | Q21: =IF(COUNTIF(Q22:Q24,"Yes")>0,"Yes","No") -> Yes | R21: =IF(COUNTIF(R22:R24,"Yes")>0,"Yes","No") -> Yes | S21: See External Dependency Register / RAID Log | T21: October Durga Puja + November Diwali capacity impact
A22: M4.1 | B22: Linkage | C22: Evaluation of multiple methods | D22: Delivery Lead + Russel | E22: M3 | F22: 21-Sep-26 | G22: 29-Sep-26 | H22: =IF(OR(F22="",G22=""),"",NETWORKDAYS.INTL(F22,G22,1,'Schedule Calendar'!$H$6:$H$30)) -> 7 | K22: =IF(OR(I22="",J22=""),"",NETWORKDAYS.INTL(I22,J22,1,'Schedule Calendar'!$H$6:$H$30)) | L22: =IF(I22<>"",I22,MAX(F22,WORKDAY(MAX(M15),1,'Schedule Calendar'!$H$6:$H$30))) -> 46377 | M22: =IF(J22<>"",J22,IF(OR(L22="",H22=""),"",WORKDAY(L22,H22-1,'Schedule Calendar'!$H$6:$H$30))) -> 46385 | N22: =IF(OR(L22="",M22=""),"",NETWORKDAYS.INTL(L22,M22,1,'Schedule Calendar'!$H$6:$H$30)) -> 7 | O22: All candidate methods evaluated against agreed methodology | P22: Not Started | Q22: Yes | R22: Yes | S22: If dataset/SME unavailable, escalate as decision blocker; no unsupported claim of performance. | T22: None
A23: M4.2 | B23: Linkage | C23: Cross-method benchmarking | D23: Senior Data Scientist | E23: M4.1 | F23: 28-Sep-26 | G23: 1-Oct-26 | H23: =IF(OR(F23="",G23=""),"",NETWORKDAYS.INTL(F23,G23,1,'Schedule Calendar'!$H$6:$H$30)) -> 4 | K23: =IF(OR(I23="",J23=""),"",NETWORKDAYS.INTL(I23,J23,1,'Schedule Calendar'!$H$6:$H$30)) | L23: =IF(I23<>"",I23,MAX(F23,WORKDAY(MAX(M22),1,'Schedule Calendar'!$H$6:$H$30))) -> 46386 | M23: =IF(J23<>"",J23,IF(OR(L23="",H23=""),"",WORKDAY(L23,H23-1,'Schedule Calendar'!$H$6:$H$30))) -> 46391 | N23: =IF(OR(L23="",M23=""),"",NETWORKDAYS.INTL(L23,M23,1,'Schedule Calendar'!$H$6:$H$30)) -> 4 | O23: Comparative benchmark completed | P23: Not Started | Q23: Yes | R23: No | S23: Use fixed evaluation set and documented metrics. | T23: None
A24: M4.3 | B24: Linkage | C24: Final method selection | D24: Delivery Lead | E24: M4.1, M4.2 | F24: 1-Oct-26 | G24: 2-Oct-26 | H24: =IF(OR(F24="",G24=""),"",NETWORKDAYS.INTL(F24,G24,1,'Schedule Calendar'!$H$6:$H$30)) -> 2 | K24: =IF(OR(I24="",J24=""),"",NETWORKDAYS.INTL(I24,J24,1,'Schedule Calendar'!$H$6:$H$30)) | L24: =IF(I24<>"",I24,MAX(F24,WORKDAY(MAX(M22,M23),1,'Schedule Calendar'!$H$6:$H$30))) -> 46392 | M24: =IF(J24<>"",J24,IF(OR(L24="",H24=""),"",WORKDAY(L24,H24-1,'Schedule Calendar'!$H$6:$H$30))) -> 46393 | N24: =IF(OR(L24="",M24=""),"",NETWORKDAYS.INTL(L24,M24,1,'Schedule Calendar'!$H$6:$H$30)) -> 2 | O24: Decision documented with evidence and trade-offs | P24: Not Started | Q24: Yes | R24: No | S24: Escalate decision if evidence is insufficient; do not select based on preference. | T24: None
A25: M5 | B25: Linkage | C25: SME Validation / Sign-off | D25: Delivery Lead | E25: M4 | F25: =IF(COUNT(F26:F28)=0,"",MIN(F26:F28)) | G25: =IF(COUNT(G26:G28)=0,"",MAX(G26:G28)) | H25: =IF(OR(F25="",G25=""),"",NETWORKDAYS.INTL(F25,G25,1,'Schedule Calendar'!$H$6:$H$30)) | I25: =IF(COUNT(I26:I28)=0,"",MIN(I26:I28)) | K25: =IF(OR(I25="",J25=""),"",NETWORKDAYS.INTL(I25,J25,1,'Schedule Calendar'!$H$6:$H$30)) | L25: =IFERROR(MIN(L26:L28),"") -> 46394 | M25: =IFERROR(MAX(M26:M28),"") -> 46402 | N25: =IF(OR(L25="",M25=""),"",NETWORKDAYS.INTL(L25,M25,1,'Schedule Calendar'!$H$6:$H$30)) -> 7 | O25: Milestone exit criteria defined in the operating model | P25: =IF(COUNTIF(P26:P28,"Red")>0,"Red",IF(COUNTIF(P26:P28,"Amber")>0,"Amber",IF(COUNTIF(P26:P28,"Blocked")>0,"Blocked",IF(COUNTIF(P26:P28,"Complete")=ROWS(P26:P28),"Complete",IF(COUNTIF(P26:P28,"Green")>0,"Green","Not Started"))))) -> Not Started | Q25: =IF(COUNTIF(Q26:Q28,"Yes")>0,"Yes","No") -> Yes | R25: =IF(COUNTIF(R26:R28,"Yes")>0,"Yes","No") -> Yes | S25: See External Dependency Register / RAID Log | T25: October Durga Puja + November Diwali capacity impact
A26: M5.1 | B26: Linkage | C26: SME validation session | D26: Delivery Lead | E26: M4 | F26: 5-Oct-26 | G26: 6-Oct-26 | H26: =IF(OR(F26="",G26=""),"",NETWORKDAYS.INTL(F26,G26,1,'Schedule Calendar'!$H$6:$H$30)) -> 2 | K26: =IF(OR(I26="",J26=""),"",NETWORKDAYS.INTL(I26,J26,1,'Schedule Calendar'!$H$6:$H$30)) | L26: =IF(I26<>"",I26,MAX(F26,WORKDAY(MAX(M21),1,'Schedule Calendar'!$H$6:$H$30))) -> 46394 | M26: =IF(J26<>"",J26,IF(OR(L26="",H26=""),"",WORKDAY(L26,H26-1,'Schedule Calendar'!$H$6:$H$30))) -> 46395 | N26: =IF(OR(L26="",M26=""),"",NETWORKDAYS.INTL(L26,M26,1,'Schedule Calendar'!$H$6:$H$30)) -> 2 | O26: SME review completed and findings logged | P26: Not Started | Q26: Yes | R26: Yes | S26: SME slot pre-booked from Aug; named backup SME/delegate; escalate no-show immediately. | T26: Durga Puja leave window begins mid-Oct
A27: M5.2 | B27: Linkage | C27: SME findings remediation | D27: Russel + AI Developer* | E27: M5.1 | F27: 6-Oct-26 | G27: 8-Oct-26 | H27: =IF(OR(F27="",G27=""),"",NETWORKDAYS.INTL(F27,G27,1,'Schedule Calendar'!$H$6:$H$30)) -> 3 | K27: =IF(OR(I27="",J27=""),"",NETWORKDAYS.INTL(I27,J27,1,'Schedule Calendar'!$H$6:$H$30)) | L27: =IF(I27<>"",I27,MAX(F27,WORKDAY(MAX(M26),1,'Schedule Calendar'!$H$6:$H$30))) -> 46398 | M27: =IF(J27<>"",J27,IF(OR(L27="",H27=""),"",WORKDAY(L27,H27-1,'Schedule Calendar'!$H$6:$H$30))) -> 46400 | N27: =IF(OR(L27="",M27=""),"",NETWORKDAYS.INTL(L27,M27,1,'Schedule Calendar'!$H$6:$H$30)) -> 3 | O27: Material findings addressed or formally accepted | P27: Not Started | Q27: Yes | R27: Yes | S27: Reserve remediation capacity before Puja; unresolved findings escalated to sponsor. | T27: Durga Puja leave window
A28: M5.3 | B28: Linkage | C28: Final SME sign-off / exception record | D28: Delivery Lead | E28: M5.2 | F28: 8-Oct-26 | G28: 9-Oct-26 | H28: =IF(OR(F28="",G28=""),"",NETWORKDAYS.INTL(F28,G28,1,'Schedule Calendar'!$H$6:$H$30)) -> 2 | K28: =IF(OR(I28="",J28=""),"",NETWORKDAYS.INTL(I28,J28,1,'Schedule Calendar'!$H$6:$H$30)) | L28: =IF(I28<>"",I28,MAX(F28,WORKDAY(MAX(M27),1,'Schedule Calendar'!$H$6:$H$30))) -> 46401 | M28: =IF(J28<>"",J28,IF(OR(L28="",H28=""),"",WORKDAY(L28,H28-1,'Schedule Calendar'!$H$6:$H$30))) -> 46402 | N28: =IF(OR(L28="",M28=""),"",NETWORKDAYS.INTL(L28,M28,1,'Schedule Calendar'!$H$6:$H$30)) -> 2 | O28: Signed validation or documented exception with decision owner | P28: Not Started | Q28: Yes | R28: Yes | S28: Delegate approval or sponsor escalation; no silent carry-over. | T28: Durga Puja leave window
A29: M6 | B29: Impact Assessment | C29: Impact Assessment Build | D29: AI Developer* + Russel | E29: M5 | F29: =IF(COUNT(F30:F32)=0,"",MIN(F30:F32)) | G29: =IF(COUNT(G30:G32)=0,"",MAX(G30:G32)) | H29: =IF(OR(F29="",G29=""),"",NETWORKDAYS.INTL(F29,G29,1,'Schedule Calendar'!$H$6:$H$30)) | I29: =IF(COUNT(I30:I32)=0,"",MIN(I30:I32)) | K29: =IF(OR(I29="",J29=""),"",NETWORKDAYS.INTL(I29,J29,1,'Schedule Calendar'!$H$6:$H$30)) | L29: =IFERROR(MIN(L30:L32),"") -> 46324 | M29: =IFERROR(MAX(M30:M32),"") -> 46358 | N29: =IF(OR(L29="",M29=""),"",NETWORKDAYS.INTL(L29,M29,1,'Schedule Calendar'!$H$6:$H$30)) -> 25 | O29: Milestone exit criteria defined in the operating model | P29: =IF(COUNTIF(P30:P32,"Red")>0,"Red",IF(COUNTIF(P30:P32,"Amber")>0,"Amber",IF(COUNTIF(P30:P32,"Blocked")>0,"Blocked",IF(COUNTIF(P30:P32,"Complete")=ROWS(P30:P32),"Complete",IF(COUNTIF(P30:P32,"Green")>0,"Green","Not Started"))))) -> Not Started | Q29: =IF(COUNTIF(Q30:Q32,"Yes")>0,"Yes","No") -> Yes | R29: =IF(COUNTIF(R30:R32,"Yes")>0,"Yes","No") -> Yes | S29: See External Dependency Register / RAID Log | T29: October Durga Puja + November Diwali capacity impact
A30: M6.1 | B30: Impact Assessment | C30: GenAI solution development | D30: AI Developer* + Russel | E30: M2 | F30: 31-Aug-26 | G30: 18-Sep-26 | H30: =IF(OR(F30="",G30=""),"",NETWORKDAYS.INTL(F30,G30,1,'Schedule Calendar'!$H$6:$H$30)) -> 15 | K30: =IF(OR(I30="",J30=""),"",NETWORKDAYS.INTL(I30,J30,1,'Schedule Calendar'!$H$6:$H$30)) | L30: =IF(I30<>"",I30,MAX(F30,WORKDAY(MAX(M8),1,'Schedule Calendar'!$H$6:$H$30))) -> 46324 | M30: =IF(J30<>"",J30,IF(OR(L30="",H30=""),"",WORKDAY(L30,H30-1,'Schedule Calendar'!$H$6:$H$30))) -> 46344 | N30: =IF(OR(L30="",M30=""),"",NETWORKDAYS.INTL(L30,M30,1,'Schedule Calendar'!$H$6:$H$30)) -> 15 | O30: Candidate solution ready | P30: Not Started | Q30: Yes | R30: Yes | S30: Fallback approved environment / offline testing during outage. | T30: None
A31: M6.2 | B31: Impact Assessment | C31: Prompt engineering | D31: AI Developer* | E31: M6.1 | F31: 7-Sep-26 | G31: 18-Sep-26 | H31: =IF(OR(F31="",G31=""),"",NETWORKDAYS.INTL(F31,G31,1,'Schedule Calendar'!$H$6:$H$30)) -> 10 | K31: =IF(OR(I31="",J31=""),"",NETWORKDAYS.INTL(I31,J31,1,'Schedule Calendar'!$H$6:$H$30)) | L31: =IF(I31<>"",I31,MAX(F31,WORKDAY(MAX(M30),1,'Schedule Calendar'!$H$6:$H$30))) -> 46345 | M31: =IF(J31<>"",J31,IF(OR(L31="",H31=""),"",WORKDAY(L31,H31-1,'Schedule Calendar'!$H$6:$H$30))) -> 46358 | N31: =IF(OR(L31="",M31=""),"",NETWORKDAYS.INTL(L31,M31,1,'Schedule Calendar'!$H$6:$H$30)) -> 10 | O31: Prompt iterations documented | P31: Not Started | Q31: Yes | R31: No | S31: Use cached test cases if API unavailable. | T31: None
A32: M6.3 | B32: Impact Assessment | C32: Retrieval tuning | D32: AI Developer* | E32: M6.1 | F32: 14-Sep-26 | G32: 25-Sep-26 | H32: =IF(OR(F32="",G32=""),"",NETWORKDAYS.INTL(F32,G32,1,'Schedule Calendar'!$H$6:$H$30)) -> 10 | K32: =IF(OR(I32="",J32=""),"",NETWORKDAYS.INTL(I32,J32,1,'Schedule Calendar'!$H$6:$H$30)) | L32: =IF(I32<>"",I32,MAX(F32,WORKDAY(MAX(M30),1,'Schedule Calendar'!$H$6:$H$30))) -> 46345 | M32: =IF(J32<>"",J32,IF(OR(L32="",H32=""),"",WORKDAY(L32,H32-1,'Schedule Calendar'!$H$6:$H$30))) -> 46358 | N32: =IF(OR(L32="",M32=""),"",NETWORKDAYS.INTL(L32,M32,1,'Schedule Calendar'!$H$6:$H$30)) -> 10 | O32: Retrieval tuned and tested | P32: Not Started | Q32: Yes | R32: Yes | S32: Offline/index rebuild fallback. | T32: None
A33: M7 | B33: Impact Assessment | C33: SME Validation / Sign-off | D33: Delivery Lead | E33: M6 | F33: =IF(COUNT(F34:F36)=0,"",MIN(F34:F36)) | G33: =IF(COUNT(G34:G36)=0,"",MAX(G34:G36)) | H33: =IF(OR(F33="",G33=""),"",NETWORKDAYS.INTL(F33,G33,1,'Schedule Calendar'!$H$6:$H$30)) | I33: =IF(COUNT(I34:I36)=0,"",MIN(I34:I36)) | K33: =IF(OR(I33="",J33=""),"",NETWORKDAYS.INTL(I33,J33,1,'Schedule Calendar'!$H$6:$H$30)) | L33: =IFERROR(MIN(L34:L36),"") -> 46359 | M33: =IFERROR(MAX(M34:M36),"") -> 46367 | N33: =IF(OR(L33="",M33=""),"",NETWORKDAYS.INTL(L33,M33,1,'Schedule Calendar'!$H$6:$H$30)) -> 7 | O33: Milestone exit criteria defined in the operating model | P33: =IF(COUNTIF(P34:P36,"Red")>0,"Red",IF(COUNTIF(P34:P36,"Amber")>0,"Amber",IF(COUNTIF(P34:P36,"Blocked")>0,"Blocked",IF(COUNTIF(P34:P36,"Complete")=ROWS(P34:P36),"Complete",IF(COUNTIF(P34:P36,"Green")>0,"Green","Not Started"))))) -> Not Started | Q33: =IF(COUNTIF(Q34:Q36,"Yes")>0,"Yes","No") -> Yes | R33: =IF(COUNTIF(R34:R36,"Yes")>0,"Yes","No") -> Yes | S33: See External Dependency Register / RAID Log | T33: October Durga Puja + November Diwali capacity impact
A34: M7.1 | B34: Impact Assessment | C34: SME validation | D34: Delivery Lead | E34: M6 | F34: 5-Oct-26 | G34: 6-Oct-26 | H34: =IF(OR(F34="",G34=""),"",NETWORKDAYS.INTL(F34,G34,1,'Schedule Calendar'!$H$6:$H$30)) -> 2 | K34: =IF(OR(I34="",J34=""),"",NETWORKDAYS.INTL(I34,J34,1,'Schedule Calendar'!$H$6:$H$30)) | L34: =IF(I34<>"",I34,MAX(F34,WORKDAY(MAX(M29),1,'Schedule Calendar'!$H$6:$H$30))) -> 46359 | M34: =IF(J34<>"",J34,IF(OR(L34="",H34=""),"",WORKDAY(L34,H34-1,'Schedule Calendar'!$H$6:$H$30))) -> 46360 | N34: =IF(OR(L34="",M34=""),"",NETWORKDAYS.INTL(L34,M34,1,'Schedule Calendar'!$H$6:$H$30)) -> 2 | O34: SME validation completed | P34: Not Started | Q34: Yes | R34: Yes | S34: Pre-booked slot + backup SME + sponsor escalation. | T34: Durga Puja leave window begins mid-Oct
A35: M7.2 | B35: Impact Assessment | C35: Remediation | D35: AI Developer* + Russel | E35: M7.1 | F35: 6-Oct-26 | G35: 8-Oct-26 | H35: =IF(OR(F35="",G35=""),"",NETWORKDAYS.INTL(F35,G35,1,'Schedule Calendar'!$H$6:$H$30)) -> 3 | K35: =IF(OR(I35="",J35=""),"",NETWORKDAYS.INTL(I35,J35,1,'Schedule Calendar'!$H$6:$H$30)) | L35: =IF(I35<>"",I35,MAX(F35,WORKDAY(MAX(M34),1,'Schedule Calendar'!$H$6:$H$30))) -> 46363 | M35: =IF(J35<>"",J35,IF(OR(L35="",H35=""),"",WORKDAY(L35,H35-1,'Schedule Calendar'!$H$6:$H$30))) -> 46365 | N35: =IF(OR(L35="",M35=""),"",NETWORKDAYS.INTL(L35,M35,1,'Schedule Calendar'!$H$6:$H$30)) -> 3 | O35: Material findings addressed / accepted | P35: Not Started | Q35: Yes | R35: Yes | S35: Protect capacity before Puja. | T35: Durga Puja leave window
A36: M7.3 | B36: Impact Assessment | C36: Documentation and final sign-off | D36: Delivery Lead | E36: M7.2 | F36: 8-Oct-26 | G36: 9-Oct-26 | H36: =IF(OR(F36="",G36=""),"",NETWORKDAYS.INTL(F36,G36,1,'Schedule Calendar'!$H$6:$H$30)) -> 2 | K36: =IF(OR(I36="",J36=""),"",NETWORKDAYS.INTL(I36,J36,1,'Schedule Calendar'!$H$6:$H$30)) | L36: =IF(I36<>"",I36,MAX(F36,WORKDAY(MAX(M35),1,'Schedule Calendar'!$H$6:$H$30))) -> 46366 | M36: =IF(J36<>"",J36,IF(OR(L36="",H36=""),"",WORKDAY(L36,H36-1,'Schedule Calendar'!$H$6:$H$30))) -> 46367 | N36: =IF(OR(L36="",M36=""),"",NETWORKDAYS.INTL(L36,M36,1,'Schedule Calendar'!$H$6:$H$30)) -> 2 | O36: Validation evidence and sign-off complete | P36: Not Started | Q36: Yes | R36: No | S36: Sponsor escalation for unresolved sign-off. | T36: Durga Puja leave window
A37: M8 | B37: Productionization | C37: Production Readiness | D37: Russel – Senior AI Developer | E37: M7 | F37: =IF(COUNT(F38:F40)=0,"",MIN(F38:F40)) | G37: =IF(COUNT(G38:G40)=0,"",MAX(G38:G40)) | H37: =IF(OR(F37="",G37=""),"",NETWORKDAYS.INTL(F37,G37,1,'Schedule Calendar'!$H$6:$H$30)) | I37: =IF(COUNT(I38:I40)=0,"",MIN(I38:I40)) | K37: =IF(OR(I37="",J37=""),"",NETWORKDAYS.INTL(I37,J37,1,'Schedule Calendar'!$H$6:$H$30)) | L37: =IFERROR(MIN(L38:L40),"") -> 46405 | M37: =IFERROR(MAX(M38:M40),"") -> 46428 | N37: =IF(OR(L37="",M37=""),"",NETWORKDAYS.INTL(L37,M37,1,'Schedule Calendar'!$H$6:$H$30)) -> 18 | O37: Milestone exit criteria defined in the operating model | P37: =IF(COUNTIF(P38:P40,"Red")>0,"Red",IF(COUNTIF(P38:P40,"Amber")>0,"Amber",IF(COUNTIF(P38:P40,"Blocked")>0,"Blocked",IF(COUNTIF(P38:P40,"Complete")=ROWS(P38:P40),"Complete",IF(COUNTIF(P38:P40,"Green")>0,"Green","Not Started"))))) -> Not Started | Q37: =IF(COUNTIF(Q38:Q40,"Yes")>0,"Yes","No") -> Yes | R37: =IF(COUNTIF(R38:R40,"Yes")>0,"Yes","No") -> Yes | S37: See External Dependency Register / RAID Log | T37: October Durga Puja + November Diwali capacity impact
A38: M8.1 | B38: Productionization | C38: Code modularization | D38: Russel – Senior AI Developer | E38: M5, M7 | F38: 12-Oct-26 | G38: 20-Oct-26 | H38: =IF(OR(F38="",G38=""),"",NETWORKDAYS.INTL(F38,G38,1,'Schedule Calendar'!$H$6:$H$30)) -> 7 | K38: =IF(OR(I38="",J38=""),"",NETWORKDAYS.INTL(I38,J38,1,'Schedule Calendar'!$H$6:$H$30)) | L38: =IF(I38<>"",I38,MAX(F38,WORKDAY(MAX(M25,M33),1,'Schedule Calendar'!$H$6:$H$30))) -> 46405 | M38: =IF(J38<>"",J38,IF(OR(L38="",H38=""),"",WORKDAY(L38,H38-1,'Schedule Calendar'!$H$6:$H$30))) -> 46413 | N38: =IF(OR(L38="",M38=""),"",NETWORKDAYS.INTL(L38,M38,1,'Schedule Calendar'!$H$6:$H$30)) -> 7 | O38: Modular, maintainable code baseline complete | P38: Not Started | Q38: Yes | R38: No | S38: Prioritise critical modules; protect post-Puja catch-up capacity. | T38: Durga Puja / reduced Kolkata capacity
A39: M8.2 | B39: Productionization | C39: Code documentation | D39: Junior Data Scientist + AI Developers | E39: M8.1 | F39: 12-Oct-26 | G39: 21-Oct-26 | H39: =IF(OR(F39="",G39=""),"",NETWORKDAYS.INTL(F39,G39,1,'Schedule Calendar'!$H$6:$H$30)) -> 8 | K39: =IF(OR(I39="",J39=""),"",NETWORKDAYS.INTL(I39,J39,1,'Schedule Calendar'!$H$6:$H$30)) | L39: =IF(I39<>"",I39,MAX(F39,WORKDAY(MAX(M38),1,'Schedule Calendar'!$H$6:$H$30))) -> 46414 | M39: =IF(J39<>"",J39,IF(OR(L39="",H39=""),"",WORKDAY(L39,H39-1,'Schedule Calendar'!$H$6:$H$30))) -> 46423 | N39: =IF(OR(L39="",M39=""),"",NETWORKDAYS.INTL(L39,M39,1,'Schedule Calendar'!$H$6:$H$30)) -> 8 | O39: Technical documentation complete and current | P39: Not Started | Q39: Yes | R39: No | S39: Documentation starts during development; do not defer all documentation to end. | T39: Durga Puja / reduced Kolkata capacity
A40: M8.3 | B40: Productionization | C40: Code KT to Tech team | D40: Russel + Delivery Lead | E40: M8.1, M8.2 | F40: 21-Oct-26 | G40: 23-Oct-26 | H40: =IF(OR(F40="",G40=""),"",NETWORKDAYS.INTL(F40,G40,1,'Schedule Calendar'!$H$6:$H$30)) -> 3 | K40: =IF(OR(I40="",J40=""),"",NETWORKDAYS.INTL(I40,J40,1,'Schedule Calendar'!$H$6:$H$30)) | L40: =IF(I40<>"",I40,MAX(F40,WORKDAY(MAX(M38,M39),1,'Schedule Calendar'!$H$6:$H$30))) -> 46426 | M40: =IF(J40<>"",J40,IF(OR(L40="",H40=""),"",WORKDAY(L40,H40-1,'Schedule Calendar'!$H$6:$H$30))) -> 46428 | N40: =IF(OR(L40="",M40=""),"",NETWORKDAYS.INTL(L40,M40,1,'Schedule Calendar'!$H$6:$H$30)) -> 3 | O40: KT completed; open technical questions logged | P40: Not Started | Q40: Yes | R40: Yes | S40: Pre-book Tech slots; provide recorded walkthrough if attendance fails. | T40: Post-Puja capacity recovery
A41: M9 | B41: Monitoring | C41: Monitoring Readiness | D41: Monitoring Team + IT | E41: M8 | F41: =IF(COUNT(F42:F45)=0,"",MIN(F42:F45)) | G41: =IF(COUNT(G42:G45)=0,"",MAX(G42:G45)) | H41: =IF(OR(F41="",G41=""),"",NETWORKDAYS.INTL(F41,G41,1,'Schedule Calendar'!$H$6:$H$30)) | I41: =IF(COUNT(I42:I45)=0,"",MIN(I42:I45)) | K41: =IF(OR(I41="",J41=""),"",NETWORKDAYS.INTL(I41,J41,1,'Schedule Calendar'!$H$6:$H$30)) | L41: =IFERROR(MIN(L42:L45),"") -> 46429 | M41: =IFERROR(MAX(M42:M45),"") -> 46458 | N41: =IF(OR(L41="",M41=""),"",NETWORKDAYS.INTL(L41,M41,1,'Schedule Calendar'!$H$6:$H$30)) -> 22 | O41: Milestone exit criteria defined in the operating model | P41: =IF(COUNTIF(P42:P45,"Red")>0,"Red",IF(COUNTIF(P42:P45,"Amber")>0,"Amber",IF(COUNTIF(P42:P45,"Blocked")>0,"Blocked",IF(COUNTIF(P42:P45,"Complete")=ROWS(P42:P45),"Complete",IF(COUNTIF(P42:P45,"Green")>0,"Green","Not Started"))))) -> Not Started | Q41: =IF(COUNTIF(Q42:Q45,"Yes")>0,"Yes","No") -> Yes | R41: =IF(COUNTIF(R42:R45,"Yes")>0,"Yes","No") -> Yes | S41: See External Dependency Register / RAID Log | T41: October Durga Puja + November Diwali capacity impact
...

Sheet Management Gantt
A1: HSBC | MANAGEMENT GANTT — PLANNED vs FORECAST vs ACTUAL
A3: ID | B3: Milestone | C3: Owner | D3: Planned Start | E3: Planned End | F3: Forecast Start | G3: Forecast End | H3: Actual Start | I3: Actual End | J3: Status | K3: Critical? | L3: 46239 | M3: 46240 | N3: 46241 | O3: 46242 | P3: 46243 | Q3: 46244 | R3: 46245 | S3: 46246 | T3: 46247 | U3: 46248 | V3: 46249 | W3: 46250 | X3: 46251 | Y3: 46252 | Z3: 46253 | AA3: 46254 | AB3: 46255 | AC3: 46256 | AD3: 46257 | AE3: 46258 | AF3: 46259 | AG3: 46260 | AH3: 46261 | AI3: 46262 | AJ3: 46263 | AK3: 46264 | AL3: 46265 | AM3: 46266 | AN3: 46267 | AO3: 46268 | AP3: 46269 | AQ3: 46270 | AR3: 46271 | AS3: 46272 | AT3: 46273 | AU3: 46274 | AV3: 46275 | AW3: 46276 | AX3: 46277 | AY3: 46278 | AZ3: 46279 | BA3: 46280 | BB3: 46281 | BC3: 46282 | BD3: 46283 | BE3: 46284 | BF3: 46285 | BG3: 46286 | BH3: 46287 | BI3: 46288 | BJ3: 46289 | BK3: 46290 | BL3: 46291 | BM3: 46292 | BN3: 46293 | BO3: 46294 | BP3: 46295 | BQ3: 46296 | BR3: 46297 | BS3: 46298 | BT3: 46299 | BU3: 46300 | BV3: 46301 | BW3: 46302 | BX3: 46303 | BY3: 46304 | BZ3: 46305 | CA3: 46306 | CB3: 46307 | CC3: 46308 | CD3: 46309 | CE3: 46310 | CF3: 46311 | CG3: 46312 | CH3: 46313 | CI3: 46314 | CJ3: 46315 | CK3: 46316 | CL3: 46317 | CM3: 46318 | CN3: 46319 | CO3: 46320 | CP3: 46321 | CQ3: 46322 | CR3: 46323 | CS3: 46324 | CT3: 46325 | CU3: 46326 | CV3: 46327 | CW3: 46328 | CX3: 46329 | CY3: 46330 | CZ3: 46331 | DA3: 46332 | DB3: 46333 | DC3: 46334 | DD3: 46335 | DE3: 46336 | DF3: 46337 | DG3: 46338 | DH3: 46339 | DI3: 46340 | DJ3: 46341 | DK3: 46342 | DL3: 46343 | DM3: 46344 | DN3: 46345 | DO3: 46346 | DP3: 46347 | DQ3: 46348 | DR3: 46349 | DS3: 46350 | DT3: 46351 | DU3: 46352 | DV3: 46353 | DW3: 46354 | DX3: 46355 | DY3: 46356
A4: M1 | B4: Scope & Delivery Baseline | C4: Delivery Lead | D4: ='Delivery Plan'!F4 -> 46239 | E4: ='Delivery Plan'!G4 | F4: ='Delivery Plan'!L4 -> 46239 | G4: ='Delivery Plan'!M4 -> 46289 | H4: ='Delivery Plan'!I4 | I4: ='Delivery Plan'!J4 -> 0 | J4: ='Delivery Plan'!P4 -> Green | K4: ='Delivery Plan'!Q4 -> Yes
A5: M2 | B5: Data Readiness | C5: Senior Data Scientist | D5: ='Delivery Plan'!F8 | E5: ='Delivery Plan'!G8 | F5: ='Delivery Plan'!L8 -> 46290 | G5: ='Delivery Plan'!M8 -> 46323 | H5: ='Delivery Plan'!I8 | I5: ='Delivery Plan'!J8 -> 0 | J5: ='Delivery Plan'!P8 -> Not Started | K5: ='Delivery Plan'!Q8 -> Yes
A6: M3 | B6: Linkage Solution Build | C6: Russel – Senior AI Developer | D6: ='Delivery Plan'!F15 | E6: ='Delivery Plan'!G15 | F6: ='Delivery Plan'!L15 -> 46324 | G6: ='Delivery Plan'!M15 -> 46374 | H6: ='Delivery Plan'!I15 | I6: ='Delivery Plan'!J15 -> 0 | J6: ='Delivery Plan'!P15 -> Not Started | K6: ='Delivery Plan'!Q15 -> Yes
A7: M4 | B7: Evaluation & Method Selection | C7: Delivery Lead | D7: ='Delivery Plan'!F21 | E7: ='Delivery Plan'!G21 | F7: ='Delivery Plan'!L21 -> 46377 | G7: ='Delivery Plan'!M21 -> 46393 | H7: ='Delivery Plan'!I21 | I7: ='Delivery Plan'!J21 -> 0 | J7: ='Delivery Plan'!P21 -> Not Started | K7: ='Delivery Plan'!Q21 -> Yes
A8: M5 | B8: SME Validation / Sign-off | C8: Delivery Lead | D8: ='Delivery Plan'!F25 | E8: ='Delivery Plan'!G25 | F8: ='Delivery Plan'!L25 -> 46394 | G8: ='Delivery Plan'!M25 -> 46402 | H8: ='Delivery Plan'!I25 | I8: ='Delivery Plan'!J25 -> 0 | J8: ='Delivery Plan'!P25 -> Not Started | K8: ='Delivery Plan'!Q25 -> Yes
A9: M6 | B9: Impact Assessment Build | C9: AI Developer* + Russel | D9: ='Delivery Plan'!F29 | E9: ='Delivery Plan'!G29 | F9: ='Delivery Plan'!L29 -> 46324 | G9: ='Delivery Plan'!M29 -> 46358 | H9: ='Delivery Plan'!I29 | I9: ='Delivery Plan'!J29 -> 0 | J9: ='Delivery Plan'!P29 -> Not Started | K9: ='Delivery Plan'!Q29 -> Yes
A10: M7 | B10: SME Validation / Sign-off | C10: Delivery Lead | D10: ='Delivery Plan'!F33 | E10: ='Delivery Plan'!G33 | F10: ='Delivery Plan'!L33 -> 46359 | G10: ='Delivery Plan'!M33 -> 46367 | H10: ='Delivery Plan'!I33 | I10: ='Delivery Plan'!J33 -> 0 | J10: ='Delivery Plan'!P33 -> Not Started | K10: ='Delivery Plan'!Q33 -> Yes
A11: M8 | B11: Production Readiness | C11: Russel – Senior AI Developer | D11: ='Delivery Plan'!F37 | E11: ='Delivery Plan'!G37 | F11: ='Delivery Plan'!L37 -> 46405 | G11: ='Delivery Plan'!M37 -> 46428 | H11: ='Delivery Plan'!I37 | I11: ='Delivery Plan'!J37 -> 0 | J11: ='Delivery Plan'!P37 -> Not Started | K11: ='Delivery Plan'!Q37 -> Yes
A12: M9 | B12: Monitoring Readiness | C12: Monitoring Team + IT | D12: ='Delivery Plan'!F41 | E12: ='Delivery Plan'!G41 | F12: ='Delivery Plan'!L41 -> 46429 | G12: ='Delivery Plan'!M41 -> 46458 | H12: ='Delivery Plan'!I41 | I12: ='Delivery Plan'!J41 -> 0 | J12: ='Delivery Plan'!P41 -> Not Started | K12: ='Delivery Plan'!Q41 -> Yes
A13: M10 | B13: Governance Approval Gate | C13: Delivery Lead | D13: ='Delivery Plan'!F46 | E13: ='Delivery Plan'!G46 | F13: ='Delivery Plan'!L46 -> 46443 | G13: ='Delivery Plan'!M46 -> 46504 | H13: ='Delivery Plan'!I46 | I13: ='Delivery Plan'!J46 -> 0 | J13: ='Delivery Plan'!P46 -> Not Started | K13: ='Delivery Plan'!Q46 -> Yes
A14: M11 | B14: Deployment Readiness | C14: IT (Delivery support) | D14: ='Delivery Plan'!F54 | E14: ='Delivery Plan'!G54 | F14: ='Delivery Plan'!L54 -> 46505 | G14: ='Delivery Plan'!M54 -> 46518 | H14: ='Delivery Plan'!I54 | I14: ='Delivery Plan'!J54 -> 0 | J14: ='Delivery Plan'!P54 -> Not Started | K14: ='Delivery Plan'!Q54 -> Yes
A15: M12 | B15: Go-Live | C15: IT (Delivery support) | D15: ='Delivery Plan'!F57 | E15: ='Delivery Plan'!G57 | F15: ='Delivery Plan'!L57 -> 46519 | G15: ='Delivery Plan'!M57 -> 46539 | H15: ='Delivery Plan'!I57 | I15: ='Delivery Plan'!J57 -> 0 | J15: ='Delivery Plan'!P57 -> Not Started | K15: ='Delivery Plan'!Q57 -> Yes
A18: Legend
A19: Planned
A20: Forecast
A21: Actual
A23: MANAGEMENT RULE
A24: Forecast beyond Planned End = schedule variance. Actual End beyond Planned End = realised variance. M1 scoping is already in progress from 05-Aug-2026.

Sheet Schedule Calendar
A1: HSBC | SCHEDULE CALENDAR & NON-WORKING DAYS
A4: Date | B4: Day | C4: Working Day? | D4: Reason / Holiday / Leave | E4: Project-wide Non-Working? | F4: Notes | H4: Project-wide Non-Working Dates
A5: 46251 | B5: Monday | C5: =IF(OR(WEEKDAY(A5,2)>5,E5="Yes"),"No","Yes") -> Yes | E5: No | F5: Project-wide closure only; individual leave remains in Resource & Capacity. | H5: Date | I5: Reason
A6: 46252 | B6: Tuesday | C6: =IF(OR(WEEKDAY(A6,2)>5,E6="Yes"),"No","Yes") -> Yes | E6: No | F6: Project-wide closure only; individual leave remains in Resource & Capacity.
A7: 46253 | B7: Wednesday | C7: =IF(OR(WEEKDAY(A7,2)>5,E7="Yes"),"No","Yes") -> Yes | E7: No | F7: Project-wide closure only; individual leave remains in Resource & Capacity.
A8: 46254 | B8: Thursday | C8: =IF(OR(WEEKDAY(A8,2)>5,E8="Yes"),"No","Yes") -> Yes | E8: No | F8: Project-wide closure only; individual leave remains in Resource & Capacity.
A9: 46255 | B9: Friday | C9: =IF(OR(WEEKDAY(A9,2)>5,E9="Yes"),"No","Yes") -> Yes | E9: No | F9: Project-wide closure only; individual leave remains in Resource & Capacity.
A10: 46256 | B10: Saturday | C10: =IF(OR(WEEKDAY(A10,2)>5,E10="Yes"),"No","Yes") -> No | E10: No | F10: Project-wide closure only; individual leave remains in Resource & Capacity.
A11: 46257 | B11: Sunday | C11: =IF(OR(WEEKDAY(A11,2)>5,E11="Yes"),"No","Yes") -> No | E11: No | F11: Project-wide closure only; individual leave remains in Resource & Capacity.
A12: 46258 | B12: Monday | C12: =IF(OR(WEEKDAY(A12,2)>5,E12="Yes"),"No","Yes") -> Yes | E12: No | F12: Project-wide closure only; individual leave remains in Resource & Capacity.
A13: 46259 | B13: Tuesday | C13: =IF(OR(WEEKDAY(A13,2)>5,E13="Yes"),"No","Yes") -> Yes | E13: No | F13: Project-wide closure only; individual leave remains in Resource & Capacity.
A14: 46260 | B14: Wednesday | C14: =IF(OR(WEEKDAY(A14,2)>5,E14="Yes"),"No","Yes") -> Yes | E14: No | F14: Project-wide closure only; individual leave remains in Resource & Capacity.
A15: 46261 | B15: Thursday | C15: =IF(OR(WEEKDAY(A15,2)>5,E15="Yes"),"No","Yes") -> Yes | E15: No | F15: Project-wide closure only; individual leave remains in Resource & Capacity.
A16: 46262 | B16: Friday | C16: =IF(OR(WEEKDAY(A16,2)>5,E16="Yes"),"No","Yes") -> Yes | E16: No | F16: Project-wide closure only; individual leave remains in Resource & Capacity.
A17: 46263 | B17: Saturday | C17: =IF(OR(WEEKDAY(A17,2)>5,E17="Yes"),"No","Yes") -> No | E17: No | F17: Project-wide closure only; individual leave remains in Resource & Capacity.
... A31: 46277 | B31: Saturday | C31: =IF(OR(WEEKDAY(A31,2)>5,E31="Yes"),"No","Yes") -> No | E31: No | F31: Project-wide closure only; individual leave remains in Resource & Capacity.
A32: 46278 | B32: Sunday | C32: =IF(OR(WEEKDAY(A32,2)>5,E32="Yes"),"No","Yes") -> No | E32: No | F32: Project-wide closure only; individual leave remains in Resource & Capacity. | H32: Only enter project-wide non-working dates here. Individual Durga Puja / Diwali leave is tracked in Resource & Capacity and should not automatically stop the project calendar.
A33: 46279 | B33: Monday | C33: =IF(OR(WEEKDAY(A33,2)>5,E33="Yes"),"No","Yes") -> Yes | E33: No | F33: Project-wide closure only; individual leave remains in Resource & Capacity.
A34: 46280 | B34: Tuesday | C34: =IF(OR(WEEKDAY(A34,2)>5,E34="Yes"),"No","Yes") -> Yes | E34: No | F34: Project-wide closure only; individual leave remains in Resource & Capacity.
A35: 46281 | B35: Wednesday | C35: =IF(OR(WEEKDAY(A35,2)>5,E35="Yes"),"No","Yes") -> Yes | E35: No | F35: Project-wide closure only; individual leave remains in Resource & Capacity.
A36: 46282 | B36: Thursday | C36: =IF(OR(WEEKDAY(A36,2)>5,E36="Yes"),"No","Yes") -> Yes | E36: No | F36: Project-wide closure only; individual leave remains in Resource & Capacity.
A37: 46283 | B37: Friday | C37: =IF(OR(WEEKDAY(A37,2)>5,E37="Yes"),"No","Yes") -> Yes | E37: No | F37: Project-wide closure only; individual leave remains in Resource & Capacity.
A38: 46284 | B38: Saturday | C38: =IF(OR(WEEKDAY(A38,2)>5,E38="Yes"),"No","Yes") -> No | E38: No | F38: Project-wide closure only; individual leave remains in Resource & Capacity.
A39: 46285 | B39: Sunday | C39: =IF(OR(WEEKDAY(A39,2)>5,E39="Yes"),"No","Yes") -> No | E39: No | F39: Project-wide closure only; individual leave remains in Resource & Capacity.
A40: 46286 | B40: Monday | C40: =IF(OR(WEEKDAY(A40,2)>5,E40="Yes"),"No","Yes") -> Yes | E40: No | F40: Project-wide closure only; individual leave remains in Resource & Capacity.
A41: 46287 | B41: Tuesday | C41: =IF(OR(WEEKDAY(A41,2)>5,E41="Yes"),"No","Yes") -> Yes | E41: No | F41: Project-wide closure only; individual leave remains in Resource & Capacity.
A42: 46288 | B42: Wednesday | C42: =IF(OR(WEEKDAY(A42,2)>5,E42="Yes"),"No","Yes") -> Yes | E42: No | F42: Project-wide closure only; individual leave remains in Resource & Capacity.
A43: 46289 | B43: Thursday | C43: =IF(OR(WEEKDAY(A43,2)>5,E43="Yes"),"No","Yes") -> Yes | E43: No | F43: Project-wide closure only; individual leave remains in Resource & Capacity.
A44: 46290 | B44: Friday | C44: =IF(OR(WEEKDAY(A44,2)>5,E44="Yes"),"No","Yes") -> Yes | E44: No | F44: Project-wide closure only; individual leave remains in Resource & Capacity.
... A110: 46356 | B110: Monday | C110: =IF(OR(WEEKDAY(A110,2)>5,E110="Yes"),"No","Yes") -> Yes | E110: No | F110: Project-wide closure only; individual leave remains in Resource & Capacity.

Sheet Resource & Capacity
A1: HSBC | RESOURCE & CAPACITY
A2: Resource | B2: Role | C2: Confirmed? | D2: Start | E2: Primary Accountability | F2: Aug Capacity | G2: Sep Capacity | H2: Oct Capacity | I2: Nov Capacity | J2: Peak Need | K2: Management Ask
A3: You | B3: Delivery Lead / Delivery Owner | C3: Yes | D3: 17-Aug-26 | E3: End-to-end delivery, QC, schedule, RAID, governance, stakeholder management, recovery; hands-on where required | F3: 100% | G3: 100% | H3: 85%* | I3: 100% | J3: Critical | K3: N/A – existing core role
A4: Russel | B4: Senior AI Developer | C4: Yes | D4: 17-Aug-26 | E4: Technical lead, architecture, core AI development, evaluation, code quality, production readiness | F4: 100% | G4: 100% | H4: 85%* | I4: 100% | J4: Critical | K4: N/A – existing core role
A5: Junior Developer | B5: Junior Data Scientist / AI Developer | C5: Yes | D5: 17-Aug-26 | E5: EDA, data preparation, testing, documentation, support to development/monitoring | F5: 100% | G5: 100% | H5: 85%* | I5: 100% | J5: High | K5: N/A – existing core role
A6: Resource 4 | B6: Senior AI/Data Scientist | C6: No | D6: Recommended 17-Aug-26 | E6: Parallel linkage / impact development, evaluation, experimentation and remediation | F6: 100% | G6: 100% | H6: 85%* | I6: 100% | J6: Critical | K6: Approve from project start
A7: Resource 5 | B7: AI Developer / Data Scientist | C7: No | D7: Recommended 17-Aug-26 or 1-Oct-26 | E7: Parallel development, prompt/retrieval, testing, documentation and capacity cover | F7: 100% | G7: 100% | H7: 85%* | I7: 100% | J7: High | K7: Approve phased; start before critical build bottleneck
A8: Monitoring Team | B8: Monitoring / Operations | C8: External dependency | D8: TBD | E8: Own monitoring operations and KPI execution; Delivery supports | F8: TBD | G8: TBD | H8: TBD | I8: TBD | J8: Critical | K8: Named team + backup required
A9: IT | B9: IT / Platform | C9: External dependency | D9: TBD | E9: Platform support, monitoring dashboard, integration, deployment and go-live | F9: TBD | G9: TBD | H9: TBD | I9: TBD | J9: Critical | K9: Named IT owner + backup + agreed response path
A12: Capacity Planning Note
A16: Management Case for Additional Resources
A17: • Hard deadline: project completion by Nov 2026; schedule has no negotiation buffer.
A18: • Delivery has two substantial AI solution tracks (Linkage + Impact Assessment) plus EDA, evaluation, SME validation, production readiness, governance and monitoring.
A19: • One Senior AI Developer creates a technical bottleneck and single point of failure.
A20: • The Delivery Lead is accountable for the outcome and therefore needs capacity to manage, QC, recover and intervene technically—not become the sole developer.
A21: • October has predictable Kolkata leave impact and November has Diwali availability risk.
A22: • Recommendation: approve two additional Data Scientist / AI Developer resources; if Management resists, at minimum approve Resource 4 for the build/evaluation phase.

Sheet External Dependency Register
A1: HSBC | EXTERNAL DEPENDENCY REGISTER
A2: ID | B2: Dependency | C2: Dependency Owner | D2: Required By | E2: Blocks | F2: Trigger / Failure Condition | G2: Impact | H2: Preventive Control | I2: Fallback / Recovery | J2: Escalation Point | K2: Status | L2: Comments
A3: ED01 | B3: REGMAP data access | C3: Data Owner | D3: 24-Aug-26 | E3: M2 | F3: Access not available by 24-Aug | G3: High | H3: Access request and confirmation before start | I3: Use approved extract; re-sequence non-data work; escalate | J3: Delivery Lead + Data Owner | K3: Open
A4: ED02 | B4: Helios data access | C4: Data Owner | D4: 24-Aug-26 | E4: M2 | F4: Access not available by 24-Aug | G4: High | H4: Pre-book access confirmation | I4: Approved extract / alternate source if available | J4: Delivery Lead + Data Owner | K4: Open
A5: ED03 | B5: Historical linked-alert / labelled data | C5: Business/SME Data Owner | D5: 4-Sep-26 | E5: M4 | F5: Insufficient linked examples | G5: Critical | H5: Treat as Day-1 dependency; quantify required population early | I5: Formal limitation decision; do not claim credible baseline/evaluation without evidence | J5: Delivery Lead + Sponsor | K5: Open
A6: ED04 | B6: SME availability – Linkage | C6: SME Lead | D6: 5-Oct-26 | E6: M5 | F6: No named SME / no slot | G6: Critical | H6: Book validation slots in Aug; named backup SME | I6: Delegate SME; sponsor escalation; re-sequence remediation but protect gate | J6: Delivery Lead + Sponsor | K6: Open
A7: ED05 | B7: SME availability – Impact Assessment | C7: SME Lead | D7: 5-Oct-26 | E7: M7 | F7: No named SME / no slot | G7: Critical | H7: Book validation slots in Aug; named backup SME | I7: Delegate SME; sponsor escalation | J7: Delivery Lead + Sponsor | K7: Open
A8: ED06 | B8: AI platform availability | C8: Platform Owner | D8: 7-Sep-26 | E8: M3/M6 | F8: Platform unavailable > agreed service window | G8: High | H8: Confirm support route; maintain test artefacts/cached data | I8: Offline testing; approved alternate endpoint/environment if available | J8: Delivery Lead + Platform Owner | K8: Open
A9: ED07 | B9: API availability / quota | C9: API / Platform Owner | D9: 7-Sep-26 | E9: M3/M6 | F9: API errors, quota or outage | G9: High | H9: Quota check and monitoring | I9: Cached responses for test cases; alternate approved API/model if available | J9: Russel + Platform Owner | K9: Open
A10: ED08 | B10: Compute / server availability | C10: Platform Owner | D10: 7-Sep-26 | E10: M3 | F10: Server unavailable / jobs blocked | G10: High | H10: Capacity reservation / support contact | I10: Approved alternate compute; queue/retry; re-sequence experiments | J10: Russel + Platform Owner | K10: Open
A11: ED09 | B11: Monitoring Team capacity | C11: Monitoring Team Lead | D11: 12-Oct-26 | E11: M9 | F11: No team or no named owner | G11: Critical | H11: Secure named team in Aug | I11: Sponsor escalation; interim manual monitoring only if formally accepted | J11: Delivery Lead + Sponsor | K11: Open
